[2024-02-05 00:28:17,322: INFO: main: welcome to our log ]
[2024-02-07 09:56:46,287: INFO: common: yaml file: config\config.yaml loaded successfully]
[2024-02-07 09:56:46,293: INFO: common: yaml file: params.yaml loaded successfully]
[2024-02-07 09:56:46,295: INFO: common: created directory at: artifacts]
[2024-02-07 09:56:46,298: INFO: common: created directory at: artifacts/data_ingestion]
[2024-02-07 09:56:46,301: INFO: 3172177572: Downloading data from https://drive.google.com/file/d/1bnQUYMn2XW2246xbOOrQsps11zJzI68Y/view?usp=sharing into file artifacts/data_ingestion/data.zip]
[2024-02-07 09:57:41,126: INFO: common: yaml file: config\config.yaml loaded successfully]
[2024-02-07 09:57:41,129: INFO: common: yaml file: params.yaml loaded successfully]
[2024-02-07 09:57:41,131: INFO: common: created directory at: artifacts]
[2024-02-07 09:57:41,132: INFO: common: created directory at: artifacts/data_ingestion]
[2024-02-07 09:57:41,134: INFO: 3172177572: Downloading data from https://drive.google.com/file/d/1bnQUYMn2XW2246xbOOrQsps11zJzI68Y/view?usp=sharing into file artifacts/data_ingestion/data.zip]
[2024-02-07 10:00:26,162: INFO: common: yaml file: config\config.yaml loaded successfully]
[2024-02-07 10:00:26,164: INFO: common: yaml file: params.yaml loaded successfully]
[2024-02-07 10:00:26,167: INFO: common: created directory at: artifacts]
[2024-02-07 10:00:26,169: INFO: common: created directory at: artifacts/data_ingestion]
[2024-02-07 10:00:26,171: INFO: 3172177572: Downloading data from https://drive.google.com/file/d/1bnQUYMn2XW2246xbOOrQsps11zJzI68Y/view?usp=sharing into file artifacts/data_ingestion/data.zip]
[2024-02-07 10:12:14,442: INFO: 3172177572: Downloaded data from https://drive.google.com/file/d/1bnQUYMn2XW2246xbOOrQsps11zJzI68Y/view?usp=sharing into file artifacts/data_ingestion/data.zip]
[2024-02-07 11:07:22,386: INFO: tempCodeRunnerFile: >>>>>> stage Data Ingestion stage started <<<<<<]
[2024-02-07 11:07:22,387: INFO: common: yaml file: config\config.yaml loaded successfully]
[2024-02-07 11:07:22,387: INFO: common: yaml file: params.yaml loaded successfully]
[2024-02-07 11:07:22,387: INFO: common: created directory at: artifacts]
[2024-02-07 11:07:22,387: INFO: common: created directory at: artifacts/data_ingestion]
[2024-02-07 11:07:22,387: INFO: data_ingestion: Downloading data from https://drive.google.com/file/d/1bnQUYMn2XW2246xbOOrQsps11zJzI68Y/view?usp=sharing into file artifacts/data_ingestion/data.zip]
[2024-02-07 11:09:48,069: ERROR: tempCodeRunnerFile: ("Connection broken: ConnectionAbortedError(10053, 'An established connection was aborted by the software in your host machine', None, 10053, None)", ConnectionAbortedError(10053, 'An established connection was aborted by the software in your host machine', None, 10053, None))]
Traceback (most recent call last):
  File "C:\Users\rajgu\anaconda3\envs\kidneyproject\lib\site-packages\urllib3\response.py", line 737, in _error_catcher
    yield
  File "C:\Users\rajgu\anaconda3\envs\kidneyproject\lib\site-packages\urllib3\response.py", line 852, in _raw_read
    data = self._fp_read(amt, read1=read1) if not fp_closed else b""
  File "C:\Users\rajgu\anaconda3\envs\kidneyproject\lib\site-packages\urllib3\response.py", line 835, in _fp_read
    return self._fp.read(amt) if amt is not None else self._fp.read()
  File "C:\Users\rajgu\anaconda3\envs\kidneyproject\lib\http\client.py", line 459, in read
    n = self.readinto(b)
  File "C:\Users\rajgu\anaconda3\envs\kidneyproject\lib\http\client.py", line 503, in readinto
    n = self.fp.readinto(b)
  File "C:\Users\rajgu\anaconda3\envs\kidneyproject\lib\socket.py", line 669, in readinto
    return self._sock.recv_into(b)
  File "C:\Users\rajgu\anaconda3\envs\kidneyproject\lib\ssl.py", line 1274, in recv_into
    return self.read(nbytes, buffer)
  File "C:\Users\rajgu\anaconda3\envs\kidneyproject\lib\ssl.py", line 1132, in read
    return self._sslobj.read(len, buffer)
ConnectionAbortedError: [WinError 10053] An established connection was aborted by the software in your host machine

The above exception was the direct cause of the following exception:

Traceback (most recent call last):
  File "C:\Users\rajgu\anaconda3\envs\kidneyproject\lib\site-packages\requests\models.py", line 816, in generate
    yield from self.raw.stream(chunk_size, decode_content=True)
  File "C:\Users\rajgu\anaconda3\envs\kidneyproject\lib\site-packages\urllib3\response.py", line 1033, in stream
    data = self.read(amt=amt, decode_content=decode_content)
  File "C:\Users\rajgu\anaconda3\envs\kidneyproject\lib\site-packages\urllib3\response.py", line 925, in read
    data = self._raw_read(amt)
  File "C:\Users\rajgu\anaconda3\envs\kidneyproject\lib\site-packages\urllib3\response.py", line 881, in _raw_read
    self._fp.close()
  File "C:\Users\rajgu\anaconda3\envs\kidneyproject\lib\contextlib.py", line 131, in __exit__
    self.gen.throw(type, value, traceback)
  File "C:\Users\rajgu\anaconda3\envs\kidneyproject\lib\site-packages\urllib3\response.py", line 754, in _error_catcher
    raise ProtocolError(f"Connection broken: {e!r}", e) from e
urllib3.exceptions.ProtocolError: ("Connection broken: ConnectionAbortedError(10053, 'An established connection was aborted by the software in your host machine', None, 10053, None)", ConnectionAbortedError(10053, 'An established connection was aborted by the software in your host machine', None, 10053, None))

During handling of the above exception, another exception occurred:

Traceback (most recent call last):
  File "c:\Users\rajgu\Desktop\major project feb\kidney-disease-classification-major-project-\tempCodeRunnerFile.py", line 12, in <module>
    data_ingestion.main()
  File "c:\users\rajgu\desktop\major project feb\kidney-disease-classification-major-project-\src\cnnClassifier\pipeline\stage_01_data_ingestion.py", line 16, in main
    data_ingestion.download_file()
  File "c:\users\rajgu\desktop\major project feb\kidney-disease-classification-major-project-\src\cnnClassifier\components\data_ingestion.py", line 33, in download_file
    raise e
  File "c:\users\rajgu\desktop\major project feb\kidney-disease-classification-major-project-\src\cnnClassifier\components\data_ingestion.py", line 28, in download_file
    gdown.download(prefix+file_id,zip_download_dir)
  File "C:\Users\rajgu\anaconda3\envs\kidneyproject\lib\site-packages\gdown\download.py", line 344, in download
    for chunk in res.iter_content(chunk_size=CHUNK_SIZE):
  File "C:\Users\rajgu\anaconda3\envs\kidneyproject\lib\site-packages\requests\models.py", line 818, in generate
    raise ChunkedEncodingError(e)
requests.exceptions.ChunkedEncodingError: ("Connection broken: ConnectionAbortedError(10053, 'An established connection was aborted by the software in your host machine', None, 10053, None)", ConnectionAbortedError(10053, 'An established connection was aborted by the software in your host machine', None, 10053, None))
[2024-02-07 11:10:05,974: INFO: main: >>>>>> stage Data Ingestion stage started <<<<<<]
[2024-02-07 11:10:05,974: INFO: common: yaml file: config\config.yaml loaded successfully]
[2024-02-07 11:10:05,974: INFO: common: yaml file: params.yaml loaded successfully]
[2024-02-07 11:10:05,974: INFO: common: created directory at: artifacts]
[2024-02-07 11:10:05,974: INFO: common: created directory at: artifacts/data_ingestion]
[2024-02-07 11:10:05,974: INFO: data_ingestion: Downloading data from https://drive.google.com/file/d/1bnQUYMn2XW2246xbOOrQsps11zJzI68Y/view?usp=sharing into file artifacts/data_ingestion/data.zip]
[2024-02-07 11:28:43,538: INFO: data_ingestion: Downloaded data from https://drive.google.com/file/d/1bnQUYMn2XW2246xbOOrQsps11zJzI68Y/view?usp=sharing into file artifacts/data_ingestion/data.zip]
[2024-02-07 11:28:58,678: INFO: main: >>>>>> stage Data Ingestion stage completed <<<<<<

x==========x]
